<?xml version="1.0" encoding="utf-8"?><testsuites><testsuite name="pytest" errors="0" failures="3" skipped="0" tests="3" time="0.113" timestamp="2024-03-29T15:43:52.355900" hostname="Mihirs-MBP-2.local.meter"><testcase classname="evals.cli.test_cli_app" name="test_add_numbers" time="0.026"><failure message="AssertionError: Adding two positive numbers should return the correct sum&#10;assert 'Result: 8' in 'Result: 2\n'">def test_add_numbers():
        # Test case 1: Adding two positive numbers
        output = subprocess.check_output(["python", "cli_app.py", "add", "5", "3"], universal_newlines=True)
&gt;       assert "Result: 8" in output, "Adding two positive numbers should return the correct sum"
E       AssertionError: Adding two positive numbers should return the correct sum
E       assert 'Result: 8' in 'Result: 2\n'

test_cli_app.py:7: AssertionError</failure></testcase><testcase classname="evals.cli.test_cli_app" name="test_multiply_numbers" time="0.021"><failure message="AssertionError: Multiplying two positive numbers should return the correct product&#10;assert 'Result: 24' in 'Result: 10\n'">def test_multiply_numbers():
        # Test case 3: Multiplying two positive numbers
        output = subprocess.check_output(["python", "cli_app.py", "multiply", "4", "6"], universal_newlines=True)
&gt;       assert "Result: 24" in output, "Multiplying two positive numbers should return the correct product"
E       AssertionError: Multiplying two positive numbers should return the correct product
E       assert 'Result: 24' in 'Result: 10\n'

test_cli_app.py:16: AssertionError</failure></testcase><testcase classname="evals.cli.test_cli_app" name="test_invalid_operation" time="0.021"><failure message="AssertionError: Invalid operation should be handled properly&#10;assert 'invalid choice' in ''&#10; +  where '' = CalledProcessError(2, ['python', 'cli_app.py', 'invalid', '5', '3']).output">def test_invalid_operation():
        # Test case 5: Providing an invalid operation
        try:
&gt;           subprocess.check_output(["python", "cli_app.py", "invalid", "5", "3"], universal_newlines=True)

test_cli_app.py:25: 
_ _ _ _ _ _ _ _ _ _ _ _ _ _ _ _ _ _ _ _ _ _ _ _ _ _ _ _ _ _ _ _ _ _ _ _ _ _ _ _ _ _ _ _ _ _ _ _ _ _ 
/Library/Frameworks/Python.framework/Versions/3.10/lib/python3.10/subprocess.py:421: in check_output
    return run(*popenargs, stdout=PIPE, timeout=timeout, check=True,
_ _ _ _ _ _ _ _ _ _ _ _ _ _ _ _ _ _ _ _ _ _ _ _ _ _ _ _ _ _ _ _ _ _ _ _ _ _ _ _ _ _ _ _ _ _ _ _ _ _ 

input = None, capture_output = False, timeout = None, check = True
popenargs = (['python', 'cli_app.py', 'invalid', '5', '3'],)
kwargs = {'stdout': -1, 'universal_newlines': True}
process = &lt;Popen: returncode: 2 args: ['python', 'cli_app.py', 'invalid', '5', '3']&gt;, stdout = ''
stderr = None, retcode = 2

    def run(*popenargs,
            input=None, capture_output=False, timeout=None, check=False, **kwargs):
        """Run command with arguments and return a CompletedProcess instance.
    
        The returned instance will have attributes args, returncode, stdout and
        stderr. By default, stdout and stderr are not captured, and those attributes
        will be None. Pass stdout=PIPE and/or stderr=PIPE in order to capture them,
        or pass capture_output=True to capture both.
    
        If check is True and the exit code was non-zero, it raises a
        CalledProcessError. The CalledProcessError object will have the return code
        in the returncode attribute, and output &amp; stderr attributes if those streams
        were captured.
    
        If timeout is given, and the process takes too long, a TimeoutExpired
        exception will be raised.
    
        There is an optional argument "input", allowing you to
        pass bytes or a string to the subprocess's stdin.  If you use this argument
        you may not also use the Popen constructor's "stdin" argument, as
        it will be used internally.
    
        By default, all communication is in bytes, and therefore any "input" should
        be bytes, and the stdout and stderr will be bytes. If in text mode, any
        "input" should be a string, and stdout and stderr will be strings decoded
        according to locale encoding, or by "encoding" if set. Text mode is
        triggered by setting any of text, encoding, errors or universal_newlines.
    
        The other arguments are the same as for the Popen constructor.
        """
        if input is not None:
            if kwargs.get('stdin') is not None:
                raise ValueError('stdin and input arguments may not both be used.')
            kwargs['stdin'] = PIPE
    
        if capture_output:
            if kwargs.get('stdout') is not None or kwargs.get('stderr') is not None:
                raise ValueError('stdout and stderr arguments may not be used '
                                 'with capture_output.')
            kwargs['stdout'] = PIPE
            kwargs['stderr'] = PIPE
    
        with Popen(*popenargs, **kwargs) as process:
            try:
                stdout, stderr = process.communicate(input, timeout=timeout)
            except TimeoutExpired as exc:
                process.kill()
                if _mswindows:
                    # Windows accumulates the output in a single blocking
                    # read() call run on child threads, with the timeout
                    # being done in a join() on those threads.  communicate()
                    # _after_ kill() is required to collect that and add it
                    # to the exception.
                    exc.stdout, exc.stderr = process.communicate()
                else:
                    # POSIX _communicate already populated the output so
                    # far into the TimeoutExpired exception.
                    process.wait()
                raise
            except:  # Including KeyboardInterrupt, communicate handled that.
                process.kill()
                # We don't call process.wait() as .__exit__ does that for us.
                raise
            retcode = process.poll()
            if check and retcode:
&gt;               raise CalledProcessError(retcode, process.args,
                                         output=stdout, stderr=stderr)
E               subprocess.CalledProcessError: Command '['python', 'cli_app.py', 'invalid', '5', '3']' returned non-zero exit status 2.

/Library/Frameworks/Python.framework/Versions/3.10/lib/python3.10/subprocess.py:526: CalledProcessError

During handling of the above exception, another exception occurred:

    def test_invalid_operation():
        # Test case 5: Providing an invalid operation
        try:
            subprocess.check_output(["python", "cli_app.py", "invalid", "5", "3"], universal_newlines=True)
            assert False, "Invalid operation should raise an exception"
        except subprocess.CalledProcessError as e:
&gt;           assert "invalid choice" in e.output, "Invalid operation should be handled properly"
E           AssertionError: Invalid operation should be handled properly
E           assert 'invalid choice' in ''
E            +  where '' = CalledProcessError(2, ['python', 'cli_app.py', 'invalid', '5', '3']).output

test_cli_app.py:28: AssertionError</failure></testcase></testsuite></testsuites>
